Ignoring exception caused at ignore_code:
Traceback (most recent call last):
  File "E:\Users\Elsword\Desktop\DecoraterBot\Async\test\resources\Dependencies\youtube_dl\YoutubeDL.py", line 682, in extract_info
    ie_result = ie.extract(url)
  File "E:\Users\Elsword\Desktop\DecoraterBot\Async\test\resources\Dependencies\youtube_dl\extractor\common.py", line 347, in extract
    return self._real_extract(url)
  File "E:\Users\Elsword\Desktop\DecoraterBot\Async\test\resources\Dependencies\youtube_dl\extractor\youtube.py", line 1321, in _real_extract
    expected=True, video_id=video_id)
youtube_dl.utils.ExtractorError: yGPoCay9qpg: YouTube said: Please sign in to view this video.

During handling of the above exception, another exception occurred:

Traceback (most recent call last):
  File "E:\Users\Elsword\Desktop\DecoraterBot\Async\test\resources\Dependencies\DecoraterBotCore\BotVoiceCommands.py", line 439, in voice_stuff_new_code
    options=ffmop, output=ffmout)
  File "E:\Users\Elsword\Desktop\DecoraterBot\Async\test\resources\Dependencies\discord\voice_client.py", line 525, in create_ytdl_player
    info = yield from self.loop.run_in_executor(None, func)
  File "asyncio\futures.py", line 361, in __iter__
  File "asyncio\tasks.py", line 296, in _wakeup
  File "asyncio\futures.py", line 274, in result
  File "concurrent\futures\thread.py", line 55, in run
  File "E:\Users\Elsword\Desktop\DecoraterBot\Async\test\resources\Dependencies\youtube_dl\YoutubeDL.py", line 693, in extract_info
    return self.process_ie_result(ie_result, download, extra_info)
  File "E:\Users\Elsword\Desktop\DecoraterBot\Async\test\resources\Dependencies\youtube_dl\YoutubeDL.py", line 854, in process_ie_result
    extra_info=extra)
  File "E:\Users\Elsword\Desktop\DecoraterBot\Async\test\resources\Dependencies\youtube_dl\YoutubeDL.py", line 746, in process_ie_result
    extra_info=extra_info)
  File "E:\Users\Elsword\Desktop\DecoraterBot\Async\test\resources\Dependencies\youtube_dl\YoutubeDL.py", line 697, in extract_info
    self.report_error(compat_str(e), e.format_traceback())
  File "E:\Users\Elsword\Desktop\DecoraterBot\Async\test\resources\Dependencies\youtube_dl\YoutubeDL.py", line 556, in report_error
    self.trouble(error_message, tb)
  File "E:\Users\Elsword\Desktop\DecoraterBot\Async\test\resources\Dependencies\youtube_dl\YoutubeDL.py", line 526, in trouble
    raise DownloadError(message, exc_info)
youtube_dl.utils.DownloadError: ERROR: yGPoCay9qpg: YouTube said: Please sign in to view this video.

During handling of the above exception, another exception occurred:

Traceback (most recent call last):
  File "E:\Users\Elsword\Desktop\DecoraterBot\Async\test\resources\Dependencies\DecoraterBotCore\Ignore.py", line 570, in ignore_code
    yield from self.DBCommandData.enable_all_commands_with_logs(client, message)
  File "E:\Users\Elsword\Desktop\DecoraterBot\Async\test\resources\Dependencies\DecoraterBotCore\Ignore.py", line 883, in enable_all_commands_with_logs
    yield from self.bot.enable_all_commands_with_logs_code(client, message)
  File "E:\Users\Elsword\Desktop\DecoraterBot\Async\test\resources\Dependencies\DecoraterBotCore\Ignore.py", line 471, in enable_all_commands_with_logs_code
    yield from self.enable_all_commands_code(client, message)
  File "E:\Users\Elsword\Desktop\DecoraterBot\Async\test\resources\Dependencies\DecoraterBotCore\Ignore.py", line 458, in enable_all_commands_code
    yield from DBVoiceCommands.voice_stuff_new(client, message)
  File "E:\Users\Elsword\Desktop\DecoraterBot\Async\test\resources\Dependencies\DecoraterBotCore\BotVoiceCommands.py", line 1489, in voice_stuff_new
    yield from self.bot.voice_stuff_new_code(client, message)
  File "E:\Users\Elsword\Desktop\DecoraterBot\Async\test\resources\Dependencies\DecoraterBotCore\BotVoiceCommands.py", line 491, in voice_stuff_new_code
    yield from client.send_message(message.channel, "Invalid or not a Youtube video URL.")
  File "E:\Users\Elsword\Desktop\DecoraterBot\Async\test\resources\Dependencies\discord\client.py", line 834, in send_message
    data = yield from self.http.send_message(channel_id, content, guild_id=guild_id, tts=tts)
  File "E:\Users\Elsword\Desktop\DecoraterBot\Async\test\resources\Dependencies\discord\http.py", line 133, in request
    raise Forbidden(r, data)
discord.errors.Forbidden: FORBIDDEN (status code: 403): Missing Access
Ignoring exception caused at ignore_code:
Traceback (most recent call last):
  File "E:\Users\Elsword\Desktop\DecoraterBot\Async\test\resources\Dependencies\youtube_dl\YoutubeDL.py", line 682, in extract_info
    ie_result = ie.extract(url)
  File "E:\Users\Elsword\Desktop\DecoraterBot\Async\test\resources\Dependencies\youtube_dl\extractor\common.py", line 347, in extract
    return self._real_extract(url)
  File "E:\Users\Elsword\Desktop\DecoraterBot\Async\test\resources\Dependencies\youtube_dl\extractor\youtube.py", line 1321, in _real_extract
    expected=True, video_id=video_id)
youtube_dl.utils.ExtractorError: yGPoCay9qpg: YouTube said: Please sign in to view this video.

During handling of the above exception, another exception occurred:

Traceback (most recent call last):
  File "E:\Users\Elsword\Desktop\DecoraterBot\Async\test\resources\Dependencies\DecoraterBotCore\BotVoiceCommands.py", line 439, in voice_stuff_new_code
    options=ffmop, output=ffmout)
  File "E:\Users\Elsword\Desktop\DecoraterBot\Async\test\resources\Dependencies\discord\voice_client.py", line 525, in create_ytdl_player
    info = yield from self.loop.run_in_executor(None, func)
  File "asyncio\futures.py", line 361, in __iter__
  File "asyncio\tasks.py", line 296, in _wakeup
  File "asyncio\futures.py", line 274, in result
  File "concurrent\futures\thread.py", line 55, in run
  File "E:\Users\Elsword\Desktop\DecoraterBot\Async\test\resources\Dependencies\youtube_dl\YoutubeDL.py", line 693, in extract_info
    return self.process_ie_result(ie_result, download, extra_info)
  File "E:\Users\Elsword\Desktop\DecoraterBot\Async\test\resources\Dependencies\youtube_dl\YoutubeDL.py", line 854, in process_ie_result
    extra_info=extra)
  File "E:\Users\Elsword\Desktop\DecoraterBot\Async\test\resources\Dependencies\youtube_dl\YoutubeDL.py", line 746, in process_ie_result
    extra_info=extra_info)
  File "E:\Users\Elsword\Desktop\DecoraterBot\Async\test\resources\Dependencies\youtube_dl\YoutubeDL.py", line 697, in extract_info
    self.report_error(compat_str(e), e.format_traceback())
  File "E:\Users\Elsword\Desktop\DecoraterBot\Async\test\resources\Dependencies\youtube_dl\YoutubeDL.py", line 556, in report_error
    self.trouble(error_message, tb)
  File "E:\Users\Elsword\Desktop\DecoraterBot\Async\test\resources\Dependencies\youtube_dl\YoutubeDL.py", line 526, in trouble
    raise DownloadError(message, exc_info)
youtube_dl.utils.DownloadError: ERROR: yGPoCay9qpg: YouTube said: Please sign in to view this video.

During handling of the above exception, another exception occurred:

Traceback (most recent call last):
  File "E:\Users\Elsword\Desktop\DecoraterBot\Async\test\resources\Dependencies\DecoraterBotCore\Ignore.py", line 570, in ignore_code
    yield from self.DBCommandData.enable_all_commands_with_logs(client, message)
  File "E:\Users\Elsword\Desktop\DecoraterBot\Async\test\resources\Dependencies\DecoraterBotCore\Ignore.py", line 883, in enable_all_commands_with_logs
    yield from self.bot.enable_all_commands_with_logs_code(client, message)
  File "E:\Users\Elsword\Desktop\DecoraterBot\Async\test\resources\Dependencies\DecoraterBotCore\Ignore.py", line 471, in enable_all_commands_with_logs_code
    yield from self.enable_all_commands_code(client, message)
  File "E:\Users\Elsword\Desktop\DecoraterBot\Async\test\resources\Dependencies\DecoraterBotCore\Ignore.py", line 458, in enable_all_commands_code
    yield from DBVoiceCommands.voice_stuff_new(client, message)
  File "E:\Users\Elsword\Desktop\DecoraterBot\Async\test\resources\Dependencies\DecoraterBotCore\BotVoiceCommands.py", line 1489, in voice_stuff_new
    yield from self.bot.voice_stuff_new_code(client, message)
  File "E:\Users\Elsword\Desktop\DecoraterBot\Async\test\resources\Dependencies\DecoraterBotCore\BotVoiceCommands.py", line 491, in voice_stuff_new_code
    yield from client.send_message(message.channel, "Invalid or not a Youtube video URL.")
  File "E:\Users\Elsword\Desktop\DecoraterBot\Async\test\resources\Dependencies\discord\client.py", line 834, in send_message
    data = yield from self.http.send_message(channel_id, content, guild_id=guild_id, tts=tts)
  File "E:\Users\Elsword\Desktop\DecoraterBot\Async\test\resources\Dependencies\discord\http.py", line 133, in request
    raise Forbidden(r, data)
discord.errors.Forbidden: FORBIDDEN (status code: 403): Missing Access
Ignoring exception caused at ignore_code:
Traceback (most recent call last):
  File "E:\Users\Elsword\Desktop\DecoraterBot\Async\test\resources\Dependencies\youtube_dl\YoutubeDL.py", line 682, in extract_info
    ie_result = ie.extract(url)
  File "E:\Users\Elsword\Desktop\DecoraterBot\Async\test\resources\Dependencies\youtube_dl\extractor\common.py", line 347, in extract
    return self._real_extract(url)
  File "E:\Users\Elsword\Desktop\DecoraterBot\Async\test\resources\Dependencies\youtube_dl\extractor\youtube.py", line 1321, in _real_extract
    expected=True, video_id=video_id)
youtube_dl.utils.ExtractorError: yGPoCay9qpg: YouTube said: Please sign in to view this video.

During handling of the above exception, another exception occurred:

Traceback (most recent call last):
  File "E:\Users\Elsword\Desktop\DecoraterBot\Async\test\resources\Dependencies\DecoraterBotCore\BotVoiceCommands.py", line 439, in voice_stuff_new_code
    options=ffmop, output=ffmout)
  File "E:\Users\Elsword\Desktop\DecoraterBot\Async\test\resources\Dependencies\discord\voice_client.py", line 525, in create_ytdl_player
    info = yield from self.loop.run_in_executor(None, func)
  File "asyncio\futures.py", line 361, in __iter__
  File "asyncio\tasks.py", line 296, in _wakeup
  File "asyncio\futures.py", line 274, in result
  File "concurrent\futures\thread.py", line 55, in run
  File "E:\Users\Elsword\Desktop\DecoraterBot\Async\test\resources\Dependencies\youtube_dl\YoutubeDL.py", line 693, in extract_info
    return self.process_ie_result(ie_result, download, extra_info)
  File "E:\Users\Elsword\Desktop\DecoraterBot\Async\test\resources\Dependencies\youtube_dl\YoutubeDL.py", line 854, in process_ie_result
    extra_info=extra)
  File "E:\Users\Elsword\Desktop\DecoraterBot\Async\test\resources\Dependencies\youtube_dl\YoutubeDL.py", line 746, in process_ie_result
    extra_info=extra_info)
  File "E:\Users\Elsword\Desktop\DecoraterBot\Async\test\resources\Dependencies\youtube_dl\YoutubeDL.py", line 697, in extract_info
    self.report_error(compat_str(e), e.format_traceback())
  File "E:\Users\Elsword\Desktop\DecoraterBot\Async\test\resources\Dependencies\youtube_dl\YoutubeDL.py", line 556, in report_error
    self.trouble(error_message, tb)
  File "E:\Users\Elsword\Desktop\DecoraterBot\Async\test\resources\Dependencies\youtube_dl\YoutubeDL.py", line 526, in trouble
    raise DownloadError(message, exc_info)
youtube_dl.utils.DownloadError: ERROR: yGPoCay9qpg: YouTube said: Please sign in to view this video.

During handling of the above exception, another exception occurred:

Traceback (most recent call last):
  File "E:\Users\Elsword\Desktop\DecoraterBot\Async\test\resources\Dependencies\DecoraterBotCore\Ignore.py", line 570, in ignore_code
    yield from self.DBCommandData.enable_all_commands_with_logs(client, message)
  File "E:\Users\Elsword\Desktop\DecoraterBot\Async\test\resources\Dependencies\DecoraterBotCore\Ignore.py", line 883, in enable_all_commands_with_logs
    yield from self.bot.enable_all_commands_with_logs_code(client, message)
  File "E:\Users\Elsword\Desktop\DecoraterBot\Async\test\resources\Dependencies\DecoraterBotCore\Ignore.py", line 471, in enable_all_commands_with_logs_code
    yield from self.enable_all_commands_code(client, message)
  File "E:\Users\Elsword\Desktop\DecoraterBot\Async\test\resources\Dependencies\DecoraterBotCore\Ignore.py", line 458, in enable_all_commands_code
    yield from DBVoiceCommands.voice_stuff_new(client, message)
  File "E:\Users\Elsword\Desktop\DecoraterBot\Async\test\resources\Dependencies\DecoraterBotCore\BotVoiceCommands.py", line 1489, in voice_stuff_new
    yield from self.bot.voice_stuff_new_code(client, message)
  File "E:\Users\Elsword\Desktop\DecoraterBot\Async\test\resources\Dependencies\DecoraterBotCore\BotVoiceCommands.py", line 491, in voice_stuff_new_code
    yield from client.send_message(message.channel, "Invalid or not a Youtube video URL.")
  File "E:\Users\Elsword\Desktop\DecoraterBot\Async\test\resources\Dependencies\discord\client.py", line 834, in send_message
    data = yield from self.http.send_message(channel_id, content, guild_id=guild_id, tts=tts)
  File "E:\Users\Elsword\Desktop\DecoraterBot\Async\test\resources\Dependencies\discord\http.py", line 133, in request
    raise Forbidden(r, data)
discord.errors.Forbidden: FORBIDDEN (status code: 403): Missing Access
Ignoring exception caused at ignore_code:
Traceback (most recent call last):
  File "E:\Users\Elsword\Desktop\DecoraterBot\Async\test\resources\Dependencies\aiohttp\connector.py", line 581, in _create_connection
    local_addr=self._local_addr)
  File "asyncio\base_events.py", line 651, in create_connection
  File "asyncio\futures.py", line 274, in result
  File "concurrent\futures\thread.py", line 55, in run
  File "socket.py", line 732, in getaddrinfo
socket.gaierror: [Errno 11004] getaddrinfo failed

The above exception was the direct cause of the following exception:

Traceback (most recent call last):
  File "E:\Users\Elsword\Desktop\DecoraterBot\Async\test\resources\Dependencies\aiohttp\connector.py", line 310, in connect
    transport, proto = yield from self._create_connection(req)
  File "E:\Users\Elsword\Desktop\DecoraterBot\Async\test\resources\Dependencies\aiohttp\connector.py", line 604, in _create_connection
    (req.host, req.port, exc.strerror)) from exc
aiohttp.errors.ClientOSError: [Errno 11004] Can not connect to discordapp.com:443 [getaddrinfo failed]

The above exception was the direct cause of the following exception:

Traceback (most recent call last):
  File "E:\Users\Elsword\Desktop\DecoraterBot\Async\test\resources\Dependencies\DecoraterBotCore\Ignore.py", line 566, in ignore_code
    yield from self.DBCommandData.cheesy_commands(client, message)
  File "E:\Users\Elsword\Desktop\DecoraterBot\Async\test\resources\Dependencies\DecoraterBotCore\Ignore.py", line 891, in cheesy_commands
    yield from self.bot.cheesy_commands_code(client, message)
  File "E:\Users\Elsword\Desktop\DecoraterBot\Async\test\resources\Dependencies\DecoraterBotCore\Ignore.py", line 536, in cheesy_commands_code
    yield from client.delete_message(message)
  File "E:\Users\Elsword\Desktop\DecoraterBot\Async\test\resources\Dependencies\discord\client.py", line 944, in delete_message
    yield from self.http.delete_message(channel.id, message.id, guild_id)
  File "E:\Users\Elsword\Desktop\DecoraterBot\Async\test\resources\Dependencies\discord\http.py", line 105, in request
    r = yield from self.session.request(method, url, **kwargs)
  File "E:\Users\Elsword\Desktop\DecoraterBot\Async\test\resources\Dependencies\aiohttp\client.py", line 529, in __iter__
    resp = yield from self._coro
  File "E:\Users\Elsword\Desktop\DecoraterBot\Async\test\resources\Dependencies\aiohttp\client.py", line 183, in _request
    conn = yield from self._connector.connect(req)
  File "E:\Users\Elsword\Desktop\DecoraterBot\Async\test\resources\Dependencies\aiohttp\connector.py", line 320, in connect
    .format(key, exc.strerror)) from exc
aiohttp.errors.ClientOSError: [Errno 11004] Cannot connect to host discordapp.com:443 ssl:True [Can not connect to discordapp.com:443 [getaddrinfo failed]]
Ignoring exception caused at _resolve_onremove_code:
Traceback (most recent call last):
  File "E:\Users\Elsword\Desktop\DecoraterBot\Async\test\resources\Dependencies\aiohttp\connector.py", line 581, in _create_connection
    local_addr=self._local_addr)
  File "asyncio\base_events.py", line 651, in create_connection
  File "asyncio\futures.py", line 274, in result
  File "concurrent\futures\thread.py", line 55, in run
  File "socket.py", line 732, in getaddrinfo
socket.gaierror: [Errno 11004] getaddrinfo failed

The above exception was the direct cause of the following exception:

Traceback (most recent call last):
  File "E:\Users\Elsword\Desktop\DecoraterBot\Async\test\resources\Dependencies\aiohttp\connector.py", line 310, in connect
    transport, proto = yield from self._create_connection(req)
  File "E:\Users\Elsword\Desktop\DecoraterBot\Async\test\resources\Dependencies\aiohttp\connector.py", line 604, in _create_connection
    (req.host, req.port, exc.strerror)) from exc
aiohttp.errors.ClientOSError: [Errno 11004] Can not connect to discordapp.com:443 [getaddrinfo failed]

The above exception was the direct cause of the following exception:

Traceback (most recent call last):
  File "E:\Users\Elsword\Desktop\DecoraterBot\Async\test\resources\Dependencies\DecoraterBotCore\Ignore.py", line 729, in _resolve_onremove_code
    banslist = yield from client.get_bans(member.server)
  File "E:\Users\Elsword\Desktop\DecoraterBot\Async\test\resources\Dependencies\discord\client.py", line 1993, in get_bans
    data = yield from self.http.get_bans(server.id)
  File "E:\Users\Elsword\Desktop\DecoraterBot\Async\test\resources\Dependencies\discord\http.py", line 105, in request
    r = yield from self.session.request(method, url, **kwargs)
  File "E:\Users\Elsword\Desktop\DecoraterBot\Async\test\resources\Dependencies\aiohttp\client.py", line 529, in __iter__
    resp = yield from self._coro
  File "E:\Users\Elsword\Desktop\DecoraterBot\Async\test\resources\Dependencies\aiohttp\client.py", line 183, in _request
    conn = yield from self._connector.connect(req)
  File "E:\Users\Elsword\Desktop\DecoraterBot\Async\test\resources\Dependencies\aiohttp\connector.py", line 320, in connect
    .format(key, exc.strerror)) from exc
aiohttp.errors.ClientOSError: [Errno 11004] Cannot connect to host discordapp.com:443 ssl:True [Can not connect to discordapp.com:443 [getaddrinfo failed]]
Ignoring exception caused at _resolve_onremove_code:
Traceback (most recent call last):
  File "E:\Users\Elsword\Desktop\DecoraterBot\Async\test\resources\Dependencies\aiohttp\connector.py", line 581, in _create_connection
    local_addr=self._local_addr)
  File "asyncio\base_events.py", line 651, in create_connection
  File "asyncio\futures.py", line 274, in result
  File "concurrent\futures\thread.py", line 55, in run
  File "socket.py", line 732, in getaddrinfo
socket.gaierror: [Errno 11004] getaddrinfo failed

The above exception was the direct cause of the following exception:

Traceback (most recent call last):
  File "E:\Users\Elsword\Desktop\DecoraterBot\Async\test\resources\Dependencies\aiohttp\connector.py", line 310, in connect
    transport, proto = yield from self._create_connection(req)
  File "E:\Users\Elsword\Desktop\DecoraterBot\Async\test\resources\Dependencies\aiohttp\connector.py", line 604, in _create_connection
    (req.host, req.port, exc.strerror)) from exc
aiohttp.errors.ClientOSError: [Errno 11004] Can not connect to discordapp.com:443 [getaddrinfo failed]

The above exception was the direct cause of the following exception:

Traceback (most recent call last):
  File "E:\Users\Elsword\Desktop\DecoraterBot\Async\test\resources\Dependencies\DecoraterBotCore\Ignore.py", line 729, in _resolve_onremove_code
    banslist = yield from client.get_bans(member.server)
  File "E:\Users\Elsword\Desktop\DecoraterBot\Async\test\resources\Dependencies\discord\client.py", line 1993, in get_bans
    data = yield from self.http.get_bans(server.id)
  File "E:\Users\Elsword\Desktop\DecoraterBot\Async\test\resources\Dependencies\discord\http.py", line 105, in request
    r = yield from self.session.request(method, url, **kwargs)
  File "E:\Users\Elsword\Desktop\DecoraterBot\Async\test\resources\Dependencies\aiohttp\client.py", line 529, in __iter__
    resp = yield from self._coro
  File "E:\Users\Elsword\Desktop\DecoraterBot\Async\test\resources\Dependencies\aiohttp\client.py", line 183, in _request
    conn = yield from self._connector.connect(req)
  File "E:\Users\Elsword\Desktop\DecoraterBot\Async\test\resources\Dependencies\aiohttp\connector.py", line 320, in connect
    .format(key, exc.strerror)) from exc
aiohttp.errors.ClientOSError: [Errno 11004] Cannot connect to host discordapp.com:443 ssl:True [Can not connect to discordapp.com:443 [getaddrinfo failed]]
